<?xml version="1.0"?>
<robot name="my_robot" xmlns:xacro="https://www.ros.org/wiki/xacro">
    <!--Color-->
    <material name="white">
        <color rgba="1 1 1 1"/>
    </material>

    <material name="orange">
        <color rgba="1 0.3 0.1 1"/>
    </material>

    <material name="blue">
        <color rgba="0.2 0.2 1 1"/>
    </material>

    <material name="black">
        <color rgba="0 0 0 1"/>
    </material>

    <!--Link1-->
    <link name = "base_link">
        <link name="base_link">
        <visual>
            <material name="white"/>
            <geometry>
                <box size="0.1 0.1 0.05"/>
            </geometry>
        </visual>
        <collision>
            <geometry>
                <box size="0.1 0.1 0.05"/>
            </geometry>
        </collision>
        <inetrial>
            <mass value="7"/>
            <inertia ixx="1e-3" ixy="0.0" ixz="0.0" iyy="1e-3" iyz="0.0" izz="1e-3"/>
        </inerial>
    </link> 


    <!--Wheels-->
    <link name = "right_wheel">
        <visual>
            <material name="black"/>
            <geometry>
                <cylinder lenght="0.03" radius="0.05"/>
            </geometry>
        </visual>

        <collision>
            <geometry>
                <cylinder lenght="0.03" radius="0.05"/>
            </geometry>
        </collision>

        <inetrial>
            <mass  value="2"/>
        </inetrial>
    </link>


    <link name = "left_wheel">
        <visual>
            <material name="black"/>
            <geometry>
                <cylinder lenght="0.03" radius="0.05"/>
            </geometry>            
        </visual>

        <collision>
             <geometry>
                <cylinder lenght="0.03" radius="0.05"/>
            </geometry>
        </collision>

        <inetrial>
            <mass value="2"/>
        </inetrial>
    </link>


    <!--IMU sensor-->
    <joint name="imu_joint" type="fixed">
        <parent link="base_link"/>
        <child link="imu_link"/>
    </joint>


    <!--left joints-->
    <joint name="left_wheel_joint" type="continuous">
        <parent link="base_link"/>
        <child link="left_wheel"/>
        <origin xyz="-0.1 0.15 0.0" rpy="0 1.5708 0"/>
        <axis xyz="0 1 0"/>
    </joint>


    <!--right joint-->
    <joint name="right_wheel_joint" type="continuous">
        <parent link="base_link"/>
        <child link="right_wheel"/>
        <origin xyz="0.1 -0.15 0.0" rpy="0 1.5708 0"/>
        <axis xyz="0 1 0"/>
    </joint>
    
</robot>